<?xml version='1.0' encoding='utf-8'?>
<robot name="biped_s14">
  <mujoco>
    <compiler meshdir="../meshes/" balanceinertia="true" discardvisual="false" />
  </mujoco>
  <!-- <link name="dummy_link" />   -->
  <link name="base_link">
    <inertial>
      <origin xyz="-0.00602072 -0.00050080 0.14657555" rpy="0 0 0" />
      <mass value="8.0177760" />
      <inertia ixx="0.08599049" ixy="0.0" ixz="0.0" iyy="0.06733455" iyz="0.0" izz="0.04204287" />
    </inertial>
    <visual>
      <origin xyz="0 0 0" rpy="0 0 0" />
      <geometry>
        <mesh filename="../meshes/torso.STL" />
      </geometry>
      <material name="1">
        <color rgba="1 1 1 1" />
      </material>
    </visual>
    <collision>
      <origin xyz="0.01 0 0.14" rpy="0 0 0" />
      <geometry>
        <box size="0.14 0.2 0.26" />
      </geometry>
    </collision>
    <collision>
      <origin xyz="-0.09 0 0.285" rpy="1.5708 0 0" />
      <geometry>
        <capsule radius="0.005" length="0.1" />
      </geometry>
    </collision>
  </link>
  <!-- <joint name="dummy_to_base_link" type="floating">
    <origin xyz="0 0 0" rpy="0 0 0" />
    <parent link="dummy_link" />
    <child link="base_link" />
  </joint> -->
  <link name="waist_yaw_link">
    <inertial>
      <origin xyz="0.00152560 0.00013413 -0.11927572" rpy="0 0 0" />
      <mass value="4.60775998" />
      <inertia ixx="0.02101970" ixy="0.0" ixz="0.0" iyy="0.01458628" iyz="0.0" izz="0.01454007" />
    </inertial>
    <visual>
      <origin xyz="0 0 0" rpy="0 0 0" />
      <geometry>
        <mesh filename="../meshes/waist.STL" />
      </geometry>
      <material name="">
        <color rgba="1 1 1 1" />
      </material>
    </visual>
    <collision>
      <origin xyz="0.005 0 -0.11" rpy="0.786 0 0" />
      <geometry>
        <box size="0.12 0.14 0.14" />
      </geometry>
    </collision>
  </link>
  <joint name="waist_yaw_joint" type="revolute">
    <origin xyz="0 0 0" rpy="0 0 0" />
    <parent link="base_link" />
    <child link="waist_yaw_link" />
    <axis xyz="0 0 1" />
    <limit lower="-2.61799387799149" upper="2.61799387799149" effort="50" velocity="8.37333333333333" />
  </joint>
  <link name="leg_l1_link">
    <inertial>
      <origin xyz="-0.00211316 -0.03290476 0.03337117" rpy="0 0 0" />
      <mass value="0.42877618" />
      <inertia ixx="0.00068733" ixy="0.00003303" ixz="-0.00003348" iyy="0.00109695" iyz="0.00004173" izz="0.00108874" />
    </inertial>
    <visual>
      <origin xyz="0 0 0" rpy="0 0 0" />
      <geometry>
        <mesh filename="../meshes/l_leg_pitch.STL" />
      </geometry>
      <material name="">
        <color rgba="1 1 1 1" />
      </material>
    </visual>
    <collision>
      <origin xyz="-0.007 -0.015 0.015" rpy="0.786 0 0" />
      <geometry>
        <box size="0.1 0.08 0.1" />
      </geometry>
    </collision>
  </link>
  <joint name="leg_l1_joint" type="revolute">
    <origin xyz="0.0 0.12151 -0.225" rpy="0 0 0" />
    <parent link="waist_yaw_link" />
    <child link="leg_l1_link" />
    <axis xyz="0 0.70711 -0.70711" />
    <limit lower="-3.228" upper="2.356" effort="180" velocity="23.55" />
    <dynamics damping="0.2" friction="0.1" />
  </joint>
  <link name="leg_l2_link">
    <inertial>
      <origin xyz="0.00559029 -0.00000102 -0.04097574" rpy="0 0 0" />
      <mass value="2.878" />
      <inertia ixx="0.00945700" ixy="0.00000006" ixz="-0.00062510" iyy="0.00895017" iyz="-0.00000229" izz="0.00346366" />
    </inertial>
    <visual>
      <origin xyz="0 0 0" rpy="0 0 0" />
      <geometry>
        <mesh filename="../meshes/l_leg_roll.STL" />
      </geometry>
      <material name="">
        <color rgba="1 1 1 1" />
      </material>
    </visual>
  </link>
  <joint name="leg_l2_joint" type="revolute">
    <origin xyz="0 0 0" rpy="0 0 0" />
    <parent link="leg_l1_link" />
    <child link="leg_l2_link" />
    <axis xyz="1 0 0" />
    <limit lower="-0.845961088441652" upper="2.41413942135856" effort="100" velocity="41.3433333333333" />
    <dynamics damping="0.2" friction="0.1" />
  </joint>
  <link name="leg_l3_link">
    <inertial>
      <origin xyz="-0.02467269 0.00082042 -0.20741352" rpy="0 0 0" />
      <mass value="1.686" />
      <inertia ixx="0.00234676" ixy="-0.00004675" ixz="-0.00029335" iyy="0.00304844" iyz="-0.00004121" izz="0.00239404" />
    </inertial>
    <visual>
      <origin xyz="0 0 0" rpy="0 0 0" />
      <geometry>
        <mesh filename="../meshes/l_leg_yaw.STL" />
      </geometry>
      <material name="">
        <color rgba="1 1 1 1" />
      </material>
    </visual>
    <collision>
      <origin xyz="-0.021 0 -0.182" rpy="1.57 0 0" />
      <geometry>
        <capsule radius="0.045" length="0.03" />
      </geometry>
    </collision>
  </link>
  <joint name="leg_l3_joint" type="revolute">
    <origin xyz="0 0 0" rpy="0 0 0" />
    <parent link="leg_l2_link" />
    <child link="leg_l3_link" />
    <axis xyz="0 0 1" />
    <limit lower="-1.658" upper="1.658" effort="100" velocity="41.3433333333333" />
    <dynamics damping="0.2" friction="0.1" />
  </joint>
  <link name="leg_l4_link">
    <inertial>
      <origin xyz="0.02466958 0.00364836 -0.12511514" rpy="0 0 0" />
      <mass value="2.0" />
      <inertia ixx="0.00661542" ixy="0.00007032" ixz="-0.00014937" iyy="0.00694493" iyz="-0.00045150" izz="0.00163682" />
    </inertial>
    <visual>
      <origin xyz="0 0 0" rpy="0 0 0" />
      <geometry>
        <mesh filename="../meshes/l_knee.STL" />
      </geometry>
      <material name="">
        <color rgba="1 1 1 1" />
      </material>
    </visual>
    <collision>
      <origin xyz="0.021 0 -0.13" rpy="0 0 0" />
      <geometry>
        <capsule radius="0.04" length="0.15" />
      </geometry>
    </collision>
    <collision>
      <origin xyz="0.07 0 0.01" rpy="1.57 0 0" />
      <geometry>
        <capsule radius="0.005" length="0.04" />
      </geometry>
    </collision>
    <collision>
      <origin xyz="0.072 0 -0.05" rpy="1.57 0 0" />
      <geometry>
        <capsule radius="0.005" length="0.02" />
      </geometry>
    </collision>
  </link>
  <joint name="leg_l4_joint" type="revolute">
    <origin xyz="-0.030 0 -0.213" rpy="0 0 0" />
    <parent link="leg_l3_link" />
    <child link="leg_l4_link" />
    <axis xyz="0 1 0" />
    <limit lower="0.0" upper="2.61799387799149" effort="180" velocity="23.55" />
    <dynamics damping="0.2" friction="0.1" />
  </joint>
  <link name="leg_l5_link">
    <inertial>
      <origin xyz="0.0 0.0 0.0" rpy="0 0 0" />
      <mass value="0.06923766 " />
      <inertia ixx="6.7e-06" ixy="0.0" ixz="0.0" iyy="6.7e-06" iyz="0.0" izz="1.172e-05" />
    </inertial>
    <visual>
      <origin xyz="0 0 0" rpy="0 0 0" />
      <geometry>
        <mesh filename="../meshes/l_foot_pitch.STL" />
      </geometry>
      <material name="">
        <color rgba="1 1 1 1" />
      </material>
    </visual>
  </link>
  <joint name="leg_l5_joint" type="revolute">
    <origin xyz="0.030 0 -0.270" rpy="0 0 0" />
    <parent link="leg_l4_link" />
    <child link="leg_l5_link" />
    <axis xyz="0 1 0" />
    <limit lower="-0.872664625997165" upper="0.523598775598299" effort="36" velocity="23.0266666666667" />
    <dynamics damping="0.2" friction="0.1" />
  </joint>
  <link name="leg_l6_link">
    <inertial>
      <origin xyz="-0.00410545 0 -0.03109022" rpy="0 0 0" />
      <mass value="0.4" />
      <inertia ixx="0.00020983" ixy="0.0" ixz="0.00010197" iyy="0.00090207" iyz="0.0" izz="0.00094979" />
    </inertial>
    <visual>
      <origin xyz="0 0 0" rpy="0 0 0" />
      <geometry>
        <mesh filename="../meshes/l_foot_roll.STL" />
      </geometry>
      <material name="">
        <color rgba="1 1 1 1" />
      </material>
    </visual>
    <collision>
      <origin xyz="0.082 0 -0.0475" rpy="0 0 0" />
      <geometry>
        <cylinder radius="0.04" length="0.008" />
      </geometry>
    </collision>
    <collision>
      <origin xyz="-0.045 0 -0.0475" rpy="0 0 0" />
      <geometry>
        <cylinder radius="0.04" length="0.008" />
      </geometry>
    </collision>
    <collision>
      <origin xyz="0.015 0 -0.0475" rpy="0 0 0" />
      <geometry>
        <box size="0.12 0.076 0.008" />
      </geometry>
    </collision>
  </link>
  <joint name="leg_l6_joint" type="revolute">
    <origin xyz="0 0 0" rpy="0 0 0" />
    <parent link="leg_l5_link" />
    <child link="leg_l6_link" />
    <axis xyz="1 0 0" />
    <limit lower="-0.261799387799149" upper="0.261799387799149" effort="36" velocity="23.0266666666667" />
    <dynamics damping="0.2" friction="0.1" />
  </joint>
  <link name="leg_r1_link">
    <inertial>
      <origin xyz="-0.00211316 0.03290476 0.03337117" rpy="0 0 0" />
      <mass value="0.42877618" />
      <inertia ixx="0.00068733" ixy="-0.00003303" ixz="-0.00003348" iyy="0.00109695" iyz="-0.00004173" izz="0.00108874" />
    </inertial>
    <visual>
      <origin xyz="0 0 0" rpy="0 0 0" />
      <geometry>
        <mesh filename="../meshes/r_leg_pitch.STL" />
      </geometry>
      <material name="">
        <color rgba="1 1 1 1" />
      </material>
    </visual>
    <collision>
      <origin xyz="-0.007 0.015 0.015" rpy="-0.786 0 0" />
      <geometry>
        <box size="0.1 0.08 0.1" />
      </geometry>
    </collision>
  </link>
  <joint name="leg_r1_joint" type="revolute">
    <origin xyz="0.0 -0.12151 -0.225" rpy="0 0 0" />
    <parent link="waist_yaw_link" />
    <child link="leg_r1_link" />
    <axis xyz="0 -0.70711 -0.70711" />
    <limit lower="-2.356" upper="3.228" effort="180" velocity="23.55" />
    <dynamics damping="0.2" friction="0.1" />
  </joint>
  <link name="leg_r2_link">
    <inertial>
      <origin xyz="0.00559029 0.00000102 -0.04097574" rpy="0 0 0" />
      <mass value="2.878" />
      <inertia ixx="0.00945700" ixy="-0.00000006" ixz="-0.00062510" iyy="0.00895017" iyz="0.00000229" izz="0.00346366" />
    </inertial>
    <visual>
      <origin xyz="0 0 0" rpy="0 0 0" />
      <geometry>
        <mesh filename="../meshes/r_leg_roll.STL" />
      </geometry>
      <material name="">
        <color rgba="1 1 1 1" />
      </material>
    </visual>
  </link>
  <joint name="leg_r2_joint" type="revolute">
    <origin xyz="0 0 0" rpy="0 0 0" />
    <parent link="leg_r1_link" />
    <child link="leg_r2_link" />
    <axis xyz="1 0 0" />
    <limit lower="-2.41413942135856" upper="0.847008285992848" effort="100" velocity="41.3433333333333" />
    <dynamics damping="0.2" friction="0.1" />
  </joint>
  <link name="leg_r3_link">
    <inertial>
      <origin xyz="-0.02467269 -0.00082042 -0.20741352" rpy="0 0 0" />
      <mass value="1.686" />
      <inertia ixx="0.00234676" ixy="0.00004675" ixz="-0.00029335" iyy="0.00304844" iyz="0.00004121" izz="0.00239404" />
    </inertial>
    <visual>
      <origin xyz="0 0 0" rpy="0 0 0" />
      <geometry>
        <mesh filename="../meshes/r_leg_yaw.STL" />
      </geometry>
      <material name="">
        <color rgba="1 1 1 1" />
      </material>
    </visual>
    <collision>
      <origin xyz="-0.021 0 -0.182" rpy="1.57 0 0" />
      <geometry>
        <capsule radius="0.045" length="0.03" />
      </geometry>
    </collision>
  </link>
  <joint name="leg_r3_joint" type="revolute">
    <origin xyz="0 0 0" rpy="0 0 0" />
    <parent link="leg_r2_link" />
    <child link="leg_r3_link" />
    <axis xyz="0 0 1" />
    <limit lower="-1.658" upper="1.658" effort="100" velocity="41.3433333333333" />
    <dynamics damping="0.2" friction="0.1" />
  </joint>
  <link name="leg_r4_link">
    <inertial>
      <origin xyz="0.02466958 -0.00364836 -0.12511514" rpy="0 0 0" />
      <mass value="2.0" />
      <inertia ixx="0.00661542" ixy="-0.00007032" ixz="-0.00014937" iyy="0.00694493" iyz="0.00045150" izz="0.00163682" />
    </inertial>
    <visual>
      <origin xyz="0 0 0" rpy="0 0 0" />
      <geometry>
        <mesh filename="../meshes/r_knee.STL" />
      </geometry>
      <material name="">
        <color rgba="1 1 1 1" />
      </material>
    </visual>
    <collision>
      <origin xyz="0.021 0 -0.13" rpy="0 0 0" />
      <geometry>
        <capsule radius="0.04" length="0.15" />
      </geometry>
    </collision>
    <collision>
      <origin xyz="0.07 0 0.01" rpy="1.57 0 0" />
      <geometry>
        <capsule radius="0.005" length="0.04" />
      </geometry>
    </collision>
    <collision>
      <origin xyz="0.072 0 -0.05" rpy="1.57 0 0" />
      <geometry>
        <capsule radius="0.005" length="0.02" />
      </geometry>
    </collision>
  </link>
  <joint name="leg_r4_joint" type="revolute">
    <origin xyz="-0.030 0 -0.213" rpy="0 0 0" />
    <parent link="leg_r3_link" />
    <child link="leg_r4_link" />
    <axis xyz="0 1 0" />
    <limit lower="0.0" upper="2.61799387799149" effort="180" velocity="23.55" />
    <dynamics damping="0.2" friction="0.1" />
  </joint>
  <link name="leg_r5_link">
    <inertial>
      <origin xyz="0.0 0.0 0.0" rpy="0 0 0" />
      <mass value="0.06923766 " />
      <inertia ixx="6.7e-06" ixy="-0.0" ixz="0.0" iyy="6.7e-06" iyz="-0.0" izz="1.172e-05" />
    </inertial>
    <visual>
      <origin xyz="0 0 0" rpy="0 0 0" />
      <geometry>
        <mesh filename="../meshes/r_foot_pitch.STL" />
      </geometry>
      <material name="">
        <color rgba="1 1 1 1" />
      </material>
    </visual>
  </link>
  <joint name="leg_r5_joint" type="revolute">
    <origin xyz="0.030 0 -0.270" rpy="0 0 0" />
    <parent link="leg_r4_link" />
    <child link="leg_r5_link" />
    <axis xyz="0 1 0" />
    <limit lower="-0.872664625997165" upper="0.523598775598299" effort="36" velocity="23.0266666666667" />
    <dynamics damping="0.2" friction="0.1" />
  </joint>
  <link name="leg_r6_link">
    <inertial>
      <origin xyz="-0.00410545 0 -0.03109022" rpy="0 0 0" />
      <mass value="0.4" />
      <inertia ixx="0.00020983" ixy="-0.0" ixz="0.00010197" iyy="0.00090207" iyz="-0.0" izz="0.00094979" />
    </inertial>
    <visual>
      <origin xyz="0 0 0" rpy="0 0 0" />
      <geometry>
        <mesh filename="../meshes/r_foot_roll.STL" />
      </geometry>
      <material name="">
        <color rgba="1 1 1 1" />
      </material>
    </visual>
    <collision>
      <origin xyz="0.082 0 -0.0475" rpy="0 0 0" />
      <geometry>
        <cylinder radius="0.04" length="0.008" />
      </geometry>
    </collision>
    <collision>
      <origin xyz="-0.045 0 -0.0475" rpy="0 0 0" />
      <geometry>
        <cylinder radius="0.04" length="0.008" />
      </geometry>
    </collision>
    <collision>
      <origin xyz="0.015 0 -0.0475" rpy="0 0 0" />
      <geometry>
        <box size="0.12 0.076 0.008" />
      </geometry>
    </collision>
  </link>
  <joint name="leg_r6_joint" type="revolute">
    <origin xyz="0 0 0" rpy="0 0 0" />
    <parent link="leg_r5_link" />
    <child link="leg_r6_link" />
    <axis xyz="1 0 0" />
    <limit lower="-0.261799387799149" upper="0.261799387799149" effort="36" velocity="23.0266666666667" />
    <dynamics damping="0.2" friction="0.1" />
  </joint>
  <link name="zarm_l1_link">
    <inertial>
      <origin xyz="0.00360552 -0.00144553 0.00001956" rpy="0 0 0" />
      <mass value="0.37301570 " />
      <inertia ixx="0.00011508" ixy="0." ixz="0." iyy="0.00013133" iyz="0." izz="0.00015171" />
    </inertial>
    <visual>
      <origin xyz="0 0 0" rpy="0 0 0" />
      <geometry>
        <mesh filename="../meshes/l_arm_pitch.STL" />
      </geometry>
      <material name="">
        <color rgba="1 1 1 1" />
      </material>
    </visual>
    <collision>
      <origin xyz="0 0 0" rpy="0 1.5708 0" />
      <geometry>
        <capsule radius="0.035" length="0.04" />
      </geometry>
    </collision>
  </link>
  <joint name="zarm_l1_joint" type="revolute">
    <origin xyz="0.00029999 0.16350292 0.23992606" rpy="0 0 0" />
    <parent link="base_link" />
    <child link="zarm_l1_link" />
    <axis xyz="0 1 0" />
    <limit lower="-3.14159265358979" upper="2.0943951023932" effort="12" velocity="7.32666666666667" />
    <dynamics damping="0.2" friction="0.1" />
  </joint>
  <link name="zarm_l2_link">
    <inertial>
      <origin xyz="0.00089424 0 -0.04238937" rpy="0 0 0" />
      <mass value="0.15112869" />
      <inertia ixx="0.00018029" ixy="0.0" ixz="0." iyy="0.00022693" iyz="0.0" izz="0.00015001" />
    </inertial>
    <visual>
      <origin xyz="0 0 0" rpy="0 0 0" />
      <geometry>
        <mesh filename="../meshes/l_arm_roll.STL" />
      </geometry>
      <material name="">
        <color rgba="1 1 1 1" />
      </material>
    </visual>
  </link>
  <joint name="zarm_l2_joint" type="revolute">
    <origin xyz="0 0 0" rpy="0 0 0" />
    <parent link="zarm_l1_link" />
    <child link="zarm_l2_link" />
    <axis xyz="1 0 0" />
    <limit lower="-0.349065850398866" upper="3.49065850398866" effort="12" velocity="7.32666666666667" />
    <dynamics damping="0.2" friction="0.1" />
  </joint>
  <link name="zarm_l3_link">
    <inertial>
      <origin xyz="-0.00011141 -0.00359387 -0.14417629" rpy="0 0 0" />
      <mass value="0.66922333 " />
      <inertia ixx="0.00170115" ixy="0." ixz="0." iyy="0.00172455" iyz="0." izz="0.00031003" />
    </inertial>
    <visual>
      <origin xyz="0 0 0" rpy="0 0 0" />
      <geometry>
        <mesh filename="../meshes/l_arm_yaw.STL" />
      </geometry>
      <material name="">
        <color rgba="1 1 1 1" />
      </material>
    </visual>
    <collision>
      <origin xyz="0 0 -0.1" rpy="0 0 0" />
      <geometry>
        <capsule radius="0.035" length="0.04" />
      </geometry>
    </collision>
  </link>
  <joint name="zarm_l3_joint" type="revolute">
    <origin xyz="0 0 0" rpy="0 0 0" />
    <parent link="zarm_l2_link" />
    <child link="zarm_l3_link" />
    <axis xyz="0 0 1" />
    <limit lower="-1.5707963267949" upper="1.5707963267949" effort="12" velocity="7.32666666666667" />
    <dynamics damping="0.2" friction="0.1" />
  </joint>
  <link name="zarm_l4_link">
    <inertial>
      <origin xyz="-0.00053745 -0.00090249 -0.09492575" rpy="0 0 0" />
      <mass value="0.16269441 " />
      <inertia ixx="0.00085779" ixy="0." ixz="0." iyy="0.00081091" iyz="0." izz="0.00012103" />
    </inertial>
    <visual>
      <origin xyz="0 0 0" rpy="0 0 0" />
      <geometry>
        <mesh filename="../meshes/l_forearm.STL" />
      </geometry>
      <material name="">
        <color rgba="1 1 1 1" />
        </material>
      </visual>
    <visual>
      <origin xyz="0 0 -0.240" rpy="0 0 0" />
      <geometry>
        <sphere radius="0.025" />
      </geometry>
    </visual>
    <collision>
      <origin xyz="0 0 0" rpy="1.57 0 0" />
      <geometry>
        <capsule radius="0.03" length="0.03" />
      </geometry>
    </collision>
    <collision>
      <origin xyz="0 0 -0.12" rpy="0 0 0" />
      <geometry>
        <capsule radius="0.025" length="0.155" />
      </geometry>
    </collision>
    <collision>
      <origin xyz="0 0 -0.240" rpy="0 0 0" />
      <geometry>
        <sphere radius="0.025" />
      </geometry>
    </collision>
  </link>
  <joint name="zarm_l4_joint" type="revolute">
    <origin xyz="0 0 -0.240" rpy="0 0 0" />
    <parent link="zarm_l3_link" />
    <child link="zarm_l4_link" />
    <axis xyz="0 1 0" />
    <limit lower="-2.26892802759263" upper="0.0" effort="12" velocity="7.32666666666667" />
    <dynamics damping="0.2" friction="0.1" />
  </joint>
  <link name="zarm_r1_link">
    <inertial>
      <origin xyz="0.00360552 0.00144553 0.00001956" rpy="0 0 0" />
      <mass value="0.37301570 " />
      <inertia ixx="0.00011508" ixy="0." ixz="0." iyy="0.00013133" iyz="0." izz="0.00015171" />
    </inertial>
    <visual>
      <origin xyz="0 0 0" rpy="0 0 0" />
      <geometry>
        <mesh filename="../meshes/r_arm_pitch.STL" />
      </geometry>
      <material name="">
        <color rgba="1 1 1 1" />
      </material>
    </visual>
    <collision>
      <origin xyz="0 0 0" rpy="0 1.5708 0" />
      <geometry>
        <capsule radius="0.035" length="0.04" />
      </geometry>
    </collision>
  </link>
  <joint name="zarm_r1_joint" type="revolute">
    <origin xyz="0.00029999 -0.16350292 0.23992606" rpy="0 0 0" />
    <parent link="base_link" />
    <child link="zarm_r1_link" />
    <axis xyz="0 1 0" />
    <limit lower="-3.14159265358979" upper="2.0943951023932" effort="12" velocity="7.32666666666667" />
    <dynamics damping="0.2" friction="0.1" />
  </joint>
  <link name="zarm_r2_link">
    <inertial>
      <origin xyz="0.00089424 0 -0.04238937" rpy="0 0 0" />
      <mass value="0.15112869" />
      <inertia ixx="0.00018029" ixy="0.0" ixz="0." iyy="0.00022693" iyz="0.0" izz="0.00015001" />
    </inertial>
    <visual>
      <origin xyz="0 0 0" rpy="0 0 0" />
      <geometry>
        <mesh filename="../meshes/r_arm_roll.STL" />
      </geometry>
      <material name="">
        <color rgba="1 1 1 1" />
      </material>
    </visual>
  </link>
  <joint name="zarm_r2_joint" type="revolute">
    <origin xyz="0 0 0" rpy="0 0 0" />
    <parent link="zarm_r1_link" />
    <child link="zarm_r2_link" />
    <axis xyz="1 0 0" />
    <limit lower="-3.49065850398866" upper="0.349065850398866" effort="12" velocity="7.32666666666667" />
    <dynamics damping="0.2" friction="0.1" />
  </joint>
  <link name="zarm_r3_link">
    <inertial>
      <origin xyz="-0.00011141 0.00359387 -0.14417629" rpy="0 0 0" />
      <mass value="0.66922333 " />
      <inertia ixx="0.00170115" ixy="0." ixz="0." iyy="0.00172455" iyz="0." izz="0.00031003" />
    </inertial>
    <visual>
      <origin xyz="0 0 0" rpy="0 0 0" />
      <geometry>
        <mesh filename="../meshes/r_arm_yaw.STL" />
      </geometry>
      <material name="">
        <color rgba="1 1 1 1" />
      </material>
    </visual>
    <collision>
      <origin xyz="0 0 -0.1" rpy="0 0 0" />
      <geometry>
        <capsule radius="0.035" length="0.04" />
      </geometry>
    </collision>
  </link>
  <joint name="zarm_r3_joint" type="revolute">
    <origin xyz="0 0 0" rpy="0 0 0" />
    <parent link="zarm_r2_link" />
    <child link="zarm_r3_link" />
    <axis xyz="0 0 1" />
    <limit lower="-1.5707963267949" upper="1.5707963267949" effort="12" velocity="7.32666666666667" />
    <dynamics damping="0.2" friction="0.1" />
  </joint>
  <link name="zarm_r4_link">
    <inertial>
      <origin xyz="-0.00053745 0.00090249 -0.09492575" rpy="0 0 0" />
      <mass value="0.16269441 " />
      <inertia ixx="0.00085779" ixy="0." ixz="0." iyy="0.00081091" iyz="0." izz="0.00012103" />
    </inertial>
    <visual>
      <origin xyz="0 0 0" rpy="0 0 0" />
      <geometry>
        <mesh filename="../meshes/r_forearm.STL" />
      </geometry>
      <material name="">
        <color rgba="1 1 1 1" />
      </material>
    </visual>
    <visual>
      <origin xyz="0 0 -0.240" rpy="0 0 0" />
      <geometry>
        <sphere radius="0.025" />
      </geometry>
    </visual>
    <collision>
      <origin xyz="0 0 0" rpy="1.57 0 0" />
      <geometry>
        <capsule radius="0.03" length="0.03" />
      </geometry>
    </collision>
    <collision>
      <origin xyz="0 0 -0.12" rpy="0 0 0" />
      <geometry>
        <capsule radius="0.025" length="0.155" />
      </geometry>
    </collision>
    <collision>
      <origin xyz="0 0 -0.240" rpy="0 0 0" />
      <geometry>
        <sphere radius="0.025" />
      </geometry>
    </collision>
  </link>
  <joint name="zarm_r4_joint" type="revolute">
    <origin xyz="0 0 -0.240" rpy="0 0 0" />
    <parent link="zarm_r3_link" />
    <child link="zarm_r4_link" />
    <axis xyz="0 1 0" />
    <limit lower="-2.26892802759263" upper="0.0" effort="12" velocity="7.32666666666667" />
    <dynamics damping="0.2" friction="0.1" />
  </joint>
  <link
    name="head_yaw">
    <inertial>
      <origin
        xyz="-0.00081546 0.0 0.01680967"
        rpy="0 0 0" />
      <mass
        value="1.03077542" />
      <inertia
        ixx="0.00215600"
        ixy="0"
        ixz="0."
        iyy="0.00189151"
        iyz="0."
        izz="0.00071659" />
    </inertial>
    <visual>
      <origin
        xyz="0 0 0"
        rpy="0 0 0" />
      <geometry>
        <mesh
          filename="../meshes/head_yaw.STL" />
      </geometry>
      <material
        name="">
        <color
          rgba="1 1 1 1" />
      </material>
    </visual>
  </link>
  <joint
    name="head_yaw"
    type="fixed">
    <origin
      xyz="0.004 0 0.35618"
      rpy="0 0 0" />
    <parent
      link="base_link" />
    <child
      link="head_yaw" />
    <axis
      xyz="0 0 1" />
  </joint>
  <link
    name="head_pitch">
    <inertial>
      <origin
        xyz="0.01466399 0.0 0.05742895"
        rpy="0 0 0" />
      <mass
        value="0.33654975 " />
      <inertia
        ixx="0.00119625"
        ixy="0."
        ixz="0."
        iyy="0.00141557"
        iyz="0."
        izz="0.00150717" />
    </inertial>
    <visual>
      <origin
        xyz="0 0 0"
        rpy="0 0 0" />
      <geometry>
        <mesh
          filename="../meshes/head_pitch.STL" />
      </geometry>
      <material
        name="">
        <color
          rgba="1 1 1 1" />
      </material>
    </visual>
    <collision>
      <origin xyz="0 0 0.035" rpy="0 0 0" />
      <geometry>
        <sphere radius="0.075" />
      </geometry>
    </collision>
  </link>
  <joint
    name="head_pitch"
    type="fixed">
    <origin
      xyz="0 0 0"
      rpy="0 0 0" />
    <parent
      link="head_yaw" />
    <child
      link="head_pitch" />
    <axis
      xyz="0 1 0" />
  </joint>
</robot>
